Workbook

Sheet Chart
A1: Calculate Jetting for Dellorto Carbs, Version 1.5
A2: Copyright (C) 2014 GUE, Licensed under GNU General Public License (GPL) Version 2.0
A4: Setup | B4: Needle Type | C4: Clip Position | D4: Carb Size | E4: Needle Jet | F4: Type (DP,DQ,ET) | G4: max HD | H4: ND | I4: HD
A5: #1 falc VHSB34 | B5: K24 | C5: 2 | D5: 34 | E5: 270 | F5: DQ | G5: =SQRT($E5^2-('Calc Data 1'!$C$45*100)^2) -> 190.01675 | H5: 50 | I5: 170
A6: #2 zu mager VHSB34 | B6: K24 | C6: 3 | D6: 34 | E6: 264 | F6: DQ | G6: =SQRT($E6^2-('Calc Data 2'!$C$45*100)^2) -> 187.72973 | H6: 50 | I6: 165
A7: #3 aktuell VHSB34 | B7: K24 | C7: 3 | D7: 34 | E7: 264 | F7: DP | G7: =SQRT($E7^2-('Calc Data 3'!$C$45*100)^2) -> 197.41265 | H7: 50 | I7: 165
A8: #4 zu fett VHSB34 | B8: K27 | C8: 2 | D8: 34 | E8: 264 | F8: DP | G8: =SQRT($E8^2-('Calc Data 4'!$C$45*100)^2) -> 173.55729 | H8: 50 | I8: 170
A9: #5 VHSA32 | B9: U16 | C9: 2 | D9: 32 | E9: 262 | F9: DQ | G9: =SQRT($E9^2-('Calc Data 5'!$C$45*100)^2) -> 168.57842 | H9: 44 | I9: 150

Sheet Needle Data
A1: Type | B1: a | C1: b | D1: c | E1: d | F1: e | G1: f | J1: Needle Type | K1: Needle Length | M1: Jet Type | N1: Needle Offset
A2: K1 | B2: 2.45 | C2: 1.75 | D2: 37 | J2: K | K2: 73.5 | M2: DP | N2: 0
A3: K2 | B3: 2.45 | C3: 1.75 | D3: 42 | J3: U | K3: 68 | M3: DQ | N3: 2
A4: K3 | B4: 2.5 | C4: 1.5 | D4: 39 | M4: ET | N4: 2
A5: K4 | B5: 2.45 | C5: 1.5 | D5: 39
A6: K5 | B6: 2.45 | C6: 1.5 | D6: 37
A7: K6 | B7: 2.45 | C7: 1.75 | D7: 39
A8: K7 | B8: 2.45 | C8: 1.25 | D8: 39
A9: K8 | B9: 2.5 | C9: 1.5 | D9: 37
A10: K9 | B10: 2.45 | C10: 1.5 | D10: 42
A11: K11 | B11: 2.5 | C11: 1.25 | D11: 39
A12: K12 | B12: 2.45 | C12: 1.75 | D12: 32
A13: K13 | B13: 2.45 | C13: 1.25 | D13: 36
A14: K14 | B14: 2.4 | C14: 1.75 | D14: 33
A15: K15 | B15: 2.6 | C15: 0.6 | D15: 36
A16: K16 | B16: 2.6 | C16: 1.75 | D16: 39
... A23: K23 | B23: 2.5 | C23: 1.8 | D23: 42
A24: K24 | B24: 2.5 | C24: 1.2 | D24: 38 | E24: 2.13 | F24: 18
A25: K25 | B25: 2.5 | C25: 1 | D25: 36 | E25: 2.15 | F25: 18
A26: K27 | B26: 2.5 | C26: 1.8 | D26: 44
A27: K28 | B27: 2.5 | C27: 1.8 | D27: 41
A28: K29 | B28: 2.45 | C28: 1.25 | D28: 42
A29: K30 | B29: 2.5 | C29: 1.4 | D29: 36 | E29: 2.15 | F29: 18
A30: K31 | B30: 2.45 | C30: 1.5 | D30: 36
A31: K32 | B31: 2.48 | C31: 1.7 | D31: 44
A32: K33 | B32: 2.5 | C32: 1.8 | D32: 44
A33: K34 | B33: 2.5 | C33: 1.4 | D33: 40 | E33: 2.11 | F33: 18
A34: K35 | B34: 2.5 | C34: 1.4 | D34: 43
A35: K36 | B35: 2.5 | C35: 1.4 | D35: 38 | E35: 2.17 | F35: 20
A36: K37 | B36: 2.5 | C36: 1.4 | D36: 39 | E36: 2.12 | F36: 18
A37: K38 | B37: 2.5 | C37: 1.4 | D37: 38 | E37: 2.13 | F37: 18
A38: K39 | B38: 2.48 | C38: 1.45 | D38: 36 | E38: 2.28 | F38: 26
A39: K40 | B39: 2.5 | C39: 1.4 | D39: 40 | E39: 2.18 | F39: 22
A40: K41 | B40: 2.5 | C40: 1.4 | D40: 40 | E40: 2.14 | F40: 22
A41: K42 | B41: 2.5 | C41: 1.4 | D41: 38 | E41: 2.16 | F41: 22
A42: K43 | B42: 2.5 | C42: 1.4 | D42: 42 | E42: 2.16 | F42: 26
A43: K44 | B43: 2.5 | C43: 1.4 | D43: 39 | E43: 2.06 | F43: 20
A44: K45 | B44: 2.48 | C44: 1.3 | D44: 36 | E44: 2.28 | F44: 26
A45: K46 | B45: 2.5 | C45: 1.4 | D45: 40 | E45: 2.15 | F45: 20
A46: K48 | B46: 2.48 | C46: 1.6 | D46: 36 | E46: 2.25 | F46: 25 | G46: 11
...

Sheet Calc Data 1
A1: Needle | B1: =Chart!$B$5 -> K24
A2: Carb Diameter | B2: =Chart!$D$5 -> 34
A3: Clip position | B3: =Chart!$C$5 -> 2
A4: Distance between clip positions | B4: 1.2
A5: Min distance needle is exposed at idle | B5: 26.4
A6: Needle length | B6: =LOOKUP(LEFT(Chart!$B$5,1),'Needle Data'!$J2:$J3,'Needle Data'!$K2:$K3) -> 73.5
A7: Needle position at idle | B7: =$B$6 - $B$5 - ($B$3-1)*$B$4 + $B$18 + ($B$2 - 34)/2 -> 47.9
A8: a | B8: =VLOOKUP($B$1,'Needle Data'!$A$2:$G$113,2,0) -> 2.5
A9: b | B9: =VLOOKUP($B$1,'Needle Data'!$A$2:$G$113,3,0) -> 1.2
A10: c | B10: =VLOOKUP($B$1,'Needle Data'!$A$2:$G$113,4,0) -> 38
A11: d | B11: =VLOOKUP($B$1,'Needle Data'!$A$2:$G$113,5,0) -> 2.13
A12: e | B12: =VLOOKUP($B$1,'Needle Data'!$A$2:$G$113,6,0) -> 18
A13: f | B13: =VLOOKUP($B$1,'Needle Data'!$A$2:$G$113,7,0)
A14: tapers | B14: =IF($B$13,3,IF($B$12,2,1)) -> 2
A15: Needle Jet | B15: =Chart!$E$5 -> 270
A16: HD | B16: =Chart!$I$5 -> 170
A17: ND | B17: =Chart!$H$5 -> 50
A18: Needle Offset because of Needle JET | B18: =LOOKUP(Chart!$F$5,'Needle Data'!$M2:$M4,'Needle Data'!$N2:$N4) -> 2
A20: taper | B20: k | C20: d
A21: 1 | B21: =IF(B$14=1,(B$8-B$9)/B$10,(B$8-B$11)/(B$10-B$12)) -> 0.0185 | C21: =IF(B$14=1,B$9,B$11) -> 2.13
A22: 2 | B22: =IF(B$14=1,0,(B$11-B$9)/(B$12-B$13)) -> 0.051666667 | C22: =IF(B$14=1,0,B$9) -> 1.2
A24: Throttle Position | B24: Needle Position | C24: Needle Diameter | D24: HD equiv. | E24: Overall
A25: 0 | B25: =$B$7-$A25*$B$2 -> 47.9 | C25: =IF($B25>B$10,B$8,IF($B25<0,0,IF($B25<B$13,B$9,IF($B25<=B$12,B$22*($B25-B$13)+B$9,B$21*($B25-B$12)+C$21)))) -> 2.5 | D25: =SQRT($B$15^2-($C25*100)^2) -> 101.98039 | E25: =$B$17*1+$D25*0 -> 50
A26: 0.05 | B26: =$B$7-$A26*$B$2 -> 46.2 | C26: =IF($B26>B$10,B$8,IF($B26<0,0,IF($B26<B$13,B$9,IF($B26<=B$12,B$22*($B26-B$13)+B$9,B$21*($B26-B$12)+C$21)))) -> 2.5 | D26: =SQRT($B$15^2-($C26*100)^2) -> 101.98039 | E26: =$B$17*0.8+$D26*0.2 -> 60.396078
A27: 0.1 | B27: =$B$7-$A27*$B$2 -> 44.5 | C27: =IF($B27>B$10,B$8,IF($B27<0,0,IF($B27<B$13,B$9,IF($B27<=B$12,B$22*($B27-B$13)+B$9,B$21*($B27-B$12)+C$21)))) -> 2.5 | D27: =SQRT($B$15^2-($C27*100)^2) -> 101.98039 | E27: =$B$17*0.6+$D27*0.4 -> 70.792156
A28: 0.15 | B28: =$B$7-$A28*$B$2 -> 42.8 | C28: =IF($B28>B$10,B$8,IF($B28<0,0,IF($B28<B$13,B$9,IF($B28<=B$12,B$22*($B28-B$13)+B$9,B$21*($B28-B$12)+C$21)))) -> 2.5 | D28: =SQRT($B$15^2-($C28*100)^2) -> 101.98039 | E28: =$B$17*0.4+$D28*0.6 -> 81.188234
A29: 0.2 | B29: =$B$7-$A29*$B$2 -> 41.1 | C29: =IF($B29>B$10,B$8,IF($B29<0,0,IF($B29<B$13,B$9,IF($B29<=B$12,B$22*($B29-B$13)+B$9,B$21*($B29-B$12)+C$21)))) -> 2.5 | D29: =SQRT($B$15^2-($C29*100)^2) -> 101.98039 | E29: =$B$17*0.2+$D29*0.8 -> 91.584312
A30: 0.25 | B30: =$B$7-$A30*$B$2 -> 39.4 | C30: =IF($B30>B$10,B$8,IF($B30<0,0,IF($B30<B$13,B$9,IF($B30<=B$12,B$22*($B30-B$13)+B$9,B$21*($B30-B$12)+C$21)))) -> 2.5 | D30: =SQRT($B$15^2-($C30*100)^2) -> 101.98039 | E30: =$B$17*0.1+$D30*0.9 -> 96.782351
A31: 0.3 | B31: =$B$7-$A31*$B$2 -> 37.7 | C31: =IF($B31>B$10,B$8,IF($B31<0,0,IF($B31<B$13,B$9,IF($B31<=B$12,B$22*($B31-B$13)+B$9,B$21*($B31-B$12)+C$21)))) -> 2.49445 | D31: =SQRT($B$15^2-($C31*100)^2) -> 103.3305 | E31: =$B$17*0.05+$D31*0.95 -> 100.66397
A32: 0.35 | B32: =$B$7-$A32*$B$2 -> 36 | C32: =IF($B32>B$10,B$8,IF($B32<0,0,IF($B32<B$13,B$9,IF($B32<=B$12,B$22*($B32-B$13)+B$9,B$21*($B32-B$12)+C$21)))) -> 2.463 | D32: =SQRT($B$15^2-($C32*100)^2) -> 110.61786 | E32: =IF($B$16<$D32,$B$16,$D32) -> 110.61786
A33: 0.4 | B33: =$B$7-$A33*$B$2 -> 34.3 | C33: =IF($B33>B$10,B$8,IF($B33<0,0,IF($B33<B$13,B$9,IF($B33<=B$12,B$22*($B33-B$13)+B$9,B$21*($B33-B$12)+C$21)))) -> 2.43155 | D33: =SQRT($B$15^2-($C33*100)^2) -> 117.3697 | E33: =IF($B$16<$D33,$B$16,$D33) -> 117.3697
A34: 0.45 | B34: =$B$7-$A34*$B$2 -> 32.6 | C34: =IF($B34>B$10,B$8,IF($B34<0,0,IF($B34<B$13,B$9,IF($B34<=B$12,B$22*($B34-B$13)+B$9,B$21*($B34-B$12)+C$21)))) -> 2.4001 | D34: =SQRT($B$15^2-($C34*100)^2) -> 123.67376 | E34: =IF($B$16<$D34,$B$16,$D34) -> 123.67376
A35: 0.5 | B35: =$B$7-$A35*$B$2 -> 30.9 | C35: =IF($B35>B$10,B$8,IF($B35<0,0,IF($B35<B$13,B$9,IF($B35<=B$12,B$22*($B35-B$13)+B$9,B$21*($B35-B$12)+C$21)))) -> 2.36865 | D35: =SQRT($B$15^2-($C35*100)^2) -> 129.59542 | E35: =IF($B$16<$D35,$B$16,$D35) -> 129.59542
A36: 0.55 | B36: =$B$7-$A36*$B$2 -> 29.2 | C36: =IF($B36>B$10,B$8,IF($B36<0,0,IF($B36<B$13,B$9,IF($B36<=B$12,B$22*($B36-B$13)+B$9,B$21*($B36-B$12)+C$21)))) -> 2.3372 | D36: =SQRT($B$15^2-($C36*100)^2) -> 135.18492 | E36: =IF($B$16<$D36,$B$16,$D36) -> 135.18492
A37: 0.6 | B37: =$B$7-$A37*$B$2 -> 27.5 | C37: =IF($B37>B$10,B$8,IF($B37<0,0,IF($B37<B$13,B$9,IF($B37<=B$12,B$22*($B37-B$13)+B$9,B$21*($B37-B$12)+C$21)))) -> 2.30575 | D37: =SQRT($B$15^2-($C37*100)^2) -> 140.48192 | E37: =IF($B$16<$D37,$B$16,$D37) -> 140.48192
A38: 0.65 | B38: =$B$7-$A38*$B$2 -> 25.8 | C38: =IF($B38>B$10,B$8,IF($B38<0,0,IF($B38<B$13,B$9,IF($B38<=B$12,B$22*($B38-B$13)+B$9,B$21*($B38-B$12)+C$21)))) -> 2.2743 | D38: =SQRT($B$15^2-($C38*100)^2) -> 145.51837 | E38: =IF($B$16<$D38,$B$16,$D38) -> 145.51837
A39: 0.7 | B39: =$B$7-$A39*$B$2 -> 24.1 | C39: =IF($B39>B$10,B$8,IF($B39<0,0,IF($B39<B$13,B$9,IF($B39<=B$12,B$22*($B39-B$13)+B$9,B$21*($B39-B$12)+C$21)))) -> 2.24285 | D39: =SQRT($B$15^2-($C39*100)^2) -> 150.32045 | E39: =IF($B$16<$D39,$B$16,$D39) -> 150.32045
A40: 0.75 | B40: =$B$7-$A40*$B$2 -> 22.4 | C40: =IF($B40>B$10,B$8,IF($B40<0,0,IF($B40<B$13,B$9,IF($B40<=B$12,B$22*($B40-B$13)+B$9,B$21*($B40-B$12)+C$21)))) -> 2.2114 | D40: =SQRT($B$15^2-($C40*100)^2) -> 154.90998 | E40: =IF($B$16<$D40,$B$16,$D40) -> 154.90998
A41: 0.8 | B41: =$B$7-$A41*$B$2 -> 20.7 | C41: =IF($B41>B$10,B$8,IF($B41<0,0,IF($B41<B$13,B$9,IF($B41<=B$12,B$22*($B41-B$13)+B$9,B$21*($B41-B$12)+C$21)))) -> 2.17995 | D41: =SQRT($B$15^2-($C41*100)^2) -> 159.3053 | E41: =IF($B$16<$D41,$B$16,$D41) -> 159.3053
A42: 0.85 | B42: =$B$7-$A42*$B$2 -> 19 | C42: =IF($B42>B$10,B$8,IF($B42<0,0,IF($B42<B$13,B$9,IF($B42<=B$12,B$22*($B42-B$13)+B$9,B$21*($B42-B$12)+C$21)))) -> 2.1485 | D42: =SQRT($B$15^2-($C42*100)^2) -> 163.5221 | E42: =IF($B$16<$D42,$B$16,$D42) -> 163.5221
...

Sheet Calc Data 2
A1: Needle | B1: =Chart!$B$6 -> K24
A2: Carb Diameter | B2: =Chart!$D$6 -> 34
A3: Clip position | B3: =Chart!$C$6 -> 3
A4: Distance between clip positions | B4: 1.2
A5: Min distance needle is exposed at idle | B5: 26.4
A6: Needle length | B6: =LOOKUP(LEFT(Chart!$B$6,1),'Needle Data'!$J2:$J3,'Needle Data'!$K2:$K3) -> 73.5
A7: Needle position at idle | B7: =$B$6 - $B$5 - ($B$3-1)*$B$4 + $B$18 + ($B$2 - 34)/2 -> 46.7
A8: a | B8: =VLOOKUP($B$1,'Needle Data'!$A$2:$G$113,2,0) -> 2.5
A9: b | B9: =VLOOKUP($B$1,'Needle Data'!$A$2:$G$113,3,0) -> 1.2
A10: c | B10: =VLOOKUP($B$1,'Needle Data'!$A$2:$G$113,4,0) -> 38
A11: d | B11: =VLOOKUP($B$1,'Needle Data'!$A$2:$G$113,5,0) -> 2.13
A12: e | B12: =VLOOKUP($B$1,'Needle Data'!$A$2:$G$113,6,0) -> 18
A13: f | B13: =VLOOKUP($B$1,'Needle Data'!$A$2:$G$113,7,0)
A14: tapers | B14: =IF($B$13,3,IF($B$12,2,1)) -> 2
A15: Needle Jet | B15: =Chart!$E$6 -> 264
A16: HD | B16: =Chart!$I$6 -> 165
A17: ND | B17: =Chart!$H$6 -> 50
A18: Needle Offset because of Needle JET | B18: =LOOKUP(Chart!$F$6,'Needle Data'!$M2:$M4,'Needle Data'!$N2:$N4) -> 2
A20: taper | B20: k | C20: d
A21: 1 | B21: =IF(B$14=1,(B$8-B$9)/B$10,(B$8-B$11)/(B$10-B$12)) -> 0.0185 | C21: =IF(B$14=1,B$9,B$11) -> 2.13
A22: 2 | B22: =IF(B$14=1,0,(B$11-B$9)/(B$12-B$13)) -> 0.051666667 | C22: =IF(B$14=1,0,B$9) -> 1.2
A24: Throttle Position | B24: Needle Position | C24: Needle Diameter | D24: HD equiv. | E24: Overall
A25: 0 | B25: =$B$7-$A25*$B$2 -> 46.7 | C25: =IF($B25>B$10,B$8,IF($B25<0,0,IF($B25<B$13,B$9,IF($B25<=B$12,B$22*($B25-B$13)+B$9,B$21*($B25-B$12)+C$21)))) -> 2.5 | D25: =SQRT($B$15^2-($C25*100)^2) -> 84.82924 | E25: =$B$17*1+$D25*0 -> 50
A26: 0.05 | B26: =$B$7-$A26*$B$2 -> 45 | C26: =IF($B26>B$10,B$8,IF($B26<0,0,IF($B26<B$13,B$9,IF($B26<=B$12,B$22*($B26-B$13)+B$9,B$21*($B26-B$12)+C$21)))) -> 2.5 | D26: =SQRT($B$15^2-($C26*100)^2) -> 84.82924 | E26: =$B$17*0.8+$D26*0.2 -> 56.965848
A27: 0.1 | B27: =$B$7-$A27*$B$2 -> 43.3 | C27: =IF($B27>B$10,B$8,IF($B27<0,0,IF($B27<B$13,B$9,IF($B27<=B$12,B$22*($B27-B$13)+B$9,B$21*($B27-B$12)+C$21)))) -> 2.5 | D27: =SQRT($B$15^2-($C27*100)^2) -> 84.82924 | E27: =$B$17*0.6+$D27*0.4 -> 63.931696
A28: 0.15 | B28: =$B$7-$A28*$B$2 -> 41.6 | C28: =IF($B28>B$10,B$8,IF($B28<0,0,IF($B28<B$13,B$9,IF($B28<=B$12,B$22*($B28-B$13)+B$9,B$21*($B28-B$12)+C$21)))) -> 2.5 | D28: =SQRT($B$15^2-($C28*100)^2) -> 84.82924 | E28: =$B$17*0.4+$D28*0.6 -> 70.897544
A29: 0.2 | B29: =$B$7-$A29*$B$2 -> 39.9 | C29: =IF($B29>B$10,B$8,IF($B29<0,0,IF($B29<B$13,B$9,IF($B29<=B$12,B$22*($B29-B$13)+B$9,B$21*($B29-B$12)+C$21)))) -> 2.5 | D29: =SQRT($B$15^2-($C29*100)^2) -> 84.82924 | E29: =$B$17*0.2+$D29*0.8 -> 77.863392
A30: 0.25 | B30: =$B$7-$A30*$B$2 -> 38.2 | C30: =IF($B30>B$10,B$8,IF($B30<0,0,IF($B30<B$13,B$9,IF($B30<=B$12,B$22*($B30-B$13)+B$9,B$21*($B30-B$12)+C$21)))) -> 2.5 | D30: =SQRT($B$15^2-($C30*100)^2) -> 84.82924 | E30: =$B$17*0.1+$D30*0.9 -> 81.346316
A31: 0.3 | B31: =$B$7-$A31*$B$2 -> 36.5 | C31: =IF($B31>B$10,B$8,IF($B31<0,0,IF($B31<B$13,B$9,IF($B31<=B$12,B$22*($B31-B$13)+B$9,B$21*($B31-B$12)+C$21)))) -> 2.47225 | D31: =SQRT($B$15^2-($C31*100)^2) -> 92.605612 | E31: =$B$17*0.05+$D31*0.95 -> 90.475331
A32: 0.35 | B32: =$B$7-$A32*$B$2 -> 34.8 | C32: =IF($B32>B$10,B$8,IF($B32<0,0,IF($B32<B$13,B$9,IF($B32<=B$12,B$22*($B32-B$13)+B$9,B$21*($B32-B$12)+C$21)))) -> 2.4408 | D32: =SQRT($B$15^2-($C32*100)^2) -> 100.60295 | E32: =IF($B$16<$D32,$B$16,$D32) -> 100.60295
A33: 0.4 | B33: =$B$7-$A33*$B$2 -> 33.1 | C33: =IF($B33>B$10,B$8,IF($B33<0,0,IF($B33<B$13,B$9,IF($B33<=B$12,B$22*($B33-B$13)+B$9,B$21*($B33-B$12)+C$21)))) -> 2.40935 | D33: =SQRT($B$15^2-($C33*100)^2) -> 107.91814 | E33: =IF($B$16<$D33,$B$16,$D33) -> 107.91814
A34: 0.45 | B34: =$B$7-$A34*$B$2 -> 31.4 | C34: =IF($B34>B$10,B$8,IF($B34<0,0,IF($B34<B$13,B$9,IF($B34<=B$12,B$22*($B34-B$13)+B$9,B$21*($B34-B$12)+C$21)))) -> 2.3779 | D34: =SQRT($B$15^2-($C34*100)^2) -> 114.6818 | E34: =IF($B$16<$D34,$B$16,$D34) -> 114.6818
A35: 0.5 | B35: =$B$7-$A35*$B$2 -> 29.7 | C35: =IF($B35>B$10,B$8,IF($B35<0,0,IF($B35<B$13,B$9,IF($B35<=B$12,B$22*($B35-B$13)+B$9,B$21*($B35-B$12)+C$21)))) -> 2.34645 | D35: =SQRT($B$15^2-($C35*100)^2) -> 120.98646 | E35: =IF($B$16<$D35,$B$16,$D35) -> 120.98646
A36: 0.55 | B36: =$B$7-$A36*$B$2 -> 28 | C36: =IF($B36>B$10,B$8,IF($B36<0,0,IF($B36<B$13,B$9,IF($B36<=B$12,B$22*($B36-B$13)+B$9,B$21*($B36-B$12)+C$21)))) -> 2.315 | D36: =SQRT($B$15^2-($C36*100)^2) -> 126.90055 | E36: =IF($B$16<$D36,$B$16,$D36) -> 126.90055
A37: 0.6 | B37: =$B$7-$A37*$B$2 -> 26.3 | C37: =IF($B37>B$10,B$8,IF($B37<0,0,IF($B37<B$13,B$9,IF($B37<=B$12,B$22*($B37-B$13)+B$9,B$21*($B37-B$12)+C$21)))) -> 2.28355 | D37: =SQRT($B$15^2-($C37*100)^2) -> 132.47639 | E37: =IF($B$16<$D37,$B$16,$D37) -> 132.47639
A38: 0.65 | B38: =$B$7-$A38*$B$2 -> 24.6 | C38: =IF($B38>B$10,B$8,IF($B38<0,0,IF($B38<B$13,B$9,IF($B38<=B$12,B$22*($B38-B$13)+B$9,B$21*($B38-B$12)+C$21)))) -> 2.2521 | D38: =SQRT($B$15^2-($C38*100)^2) -> 137.75506 | E38: =IF($B$16<$D38,$B$16,$D38) -> 137.75506
A39: 0.7 | B39: =$B$7-$A39*$B$2 -> 22.9 | C39: =IF($B39>B$10,B$8,IF($B39<0,0,IF($B39<B$13,B$9,IF($B39<=B$12,B$22*($B39-B$13)+B$9,B$21*($B39-B$12)+C$21)))) -> 2.22065 | D39: =SQRT($B$15^2-($C39*100)^2) -> 142.76952 | E39: =IF($B$16<$D39,$B$16,$D39) -> 142.76952
A40: 0.75 | B40: =$B$7-$A40*$B$2 -> 21.2 | C40: =IF($B40>B$10,B$8,IF($B40<0,0,IF($B40<B$13,B$9,IF($B40<=B$12,B$22*($B40-B$13)+B$9,B$21*($B40-B$12)+C$21)))) -> 2.1892 | D40: =SQRT($B$15^2-($C40*100)^2) -> 147.54672 | E40: =IF($B$16<$D40,$B$16,$D40) -> 147.54672
A41: 0.8 | B41: =$B$7-$A41*$B$2 -> 19.5 | C41: =IF($B41>B$10,B$8,IF($B41<0,0,IF($B41<B$13,B$9,IF($B41<=B$12,B$22*($B41-B$13)+B$9,B$21*($B41-B$12)+C$21)))) -> 2.15775 | D41: =SQRT($B$15^2-($C41*100)^2) -> 152.109 | E41: =IF($B$16<$D41,$B$16,$D41) -> 152.109
A42: 0.85 | B42: =$B$7-$A42*$B$2 -> 17.8 | C42: =IF($B42>B$10,B$8,IF($B42<0,0,IF($B42<B$13,B$9,IF($B42<=B$12,B$22*($B42-B$13)+B$9,B$21*($B42-B$12)+C$21)))) -> 2.1196667 | D42: =SQRT($B$15^2-($C42*100)^2) -> 157.37259 | E42: =IF($B$16<$D42,$B$16,$D42) -> 157.37259
...

Sheet Calc Data 3
A1: Needle | B1: =Chart!$B$7 -> K24
A2: Carb Diameter | B2: =Chart!$D$7 -> 34
A3: Clip position | B3: =Chart!$C$7 -> 3
A4: Distance between clip positions | B4: 1.2
A5: Min distance needle is exposed at idle | B5: 26.4
A6: Needle length | B6: =LOOKUP(LEFT(Chart!$B$7,1),'Needle Data'!$J2:$J3,'Needle Data'!$K2:$K3) -> 73.5
A7: Needle position at idle | B7: =$B$6 - $B$5 - ($B$3-1)*$B$4 + $B$18 + ($B$2 - 34)/2 -> 44.7
A8: a | B8: =VLOOKUP($B$1,'Needle Data'!$A$2:$G$113,2,0) -> 2.5
A9: b | B9: =VLOOKUP($B$1,'Needle Data'!$A$2:$G$113,3,0) -> 1.2
A10: c | B10: =VLOOKUP($B$1,'Needle Data'!$A$2:$G$113,4,0) -> 38
A11: d | B11: =VLOOKUP($B$1,'Needle Data'!$A$2:$G$113,5,0) -> 2.13
A12: e | B12: =VLOOKUP($B$1,'Needle Data'!$A$2:$G$113,6,0) -> 18
A13: f | B13: =VLOOKUP($B$1,'Needle Data'!$A$2:$G$113,7,0)
A14: tapers | B14: =IF($B$13,3,IF($B$12,2,1)) -> 2
A15: Needle Jet | B15: =Chart!$E$7 -> 264
A16: HD | B16: =Chart!$I$7 -> 165
A17: ND | B17: =Chart!$H$7 -> 50
A18: Needle Offset because of Needle JET | B18: =LOOKUP(Chart!$F$7,'Needle Data'!$M2:$M4,'Needle Data'!$N2:$N4) -> 0
A20: taper | B20: k | C20: d
A21: 1 | B21: =IF(B$14=1,(B$8-B$9)/B$10,(B$8-B$11)/(B$10-B$12)) -> 0.0185 | C21: =IF(B$14=1,B$9,B$11) -> 2.13
A22: 2 | B22: =IF(B$14=1,0,(B$11-B$9)/(B$12-B$13)) -> 0.051666667 | C22: =IF(B$14=1,0,B$9) -> 1.2
A24: Throttle Position | B24: Needle Position | C24: Needle Diameter | D24: HD equiv. | E24: Overall
A25: 0 | B25: =$B$7-$A25*$B$2 -> 44.7 | C25: =IF($B25>B$10,B$8,IF($B25<0,0,IF($B25<B$13,B$9,IF($B25<=B$12,B$22*($B25-B$13)+B$9,B$21*($B25-B$12)+C$21)))) -> 2.5 | D25: =SQRT($B$15^2-($C25*100)^2) -> 84.82924 | E25: =$B$17*1+$D25*0 -> 50
A26: 0.05 | B26: =$B$7-$A26*$B$2 -> 43 | C26: =IF($B26>B$10,B$8,IF($B26<0,0,IF($B26<B$13,B$9,IF($B26<=B$12,B$22*($B26-B$13)+B$9,B$21*($B26-B$12)+C$21)))) -> 2.5 | D26: =SQRT($B$15^2-($C26*100)^2) -> 84.82924 | E26: =$B$17*0.8+$D26*0.2 -> 56.965848
A27: 0.1 | B27: =$B$7-$A27*$B$2 -> 41.3 | C27: =IF($B27>B$10,B$8,IF($B27<0,0,IF($B27<B$13,B$9,IF($B27<=B$12,B$22*($B27-B$13)+B$9,B$21*($B27-B$12)+C$21)))) -> 2.5 | D27: =SQRT($B$15^2-($C27*100)^2) -> 84.82924 | E27: =$B$17*0.6+$D27*0.4 -> 63.931696
A28: 0.15 | B28: =$B$7-$A28*$B$2 -> 39.6 | C28: =IF($B28>B$10,B$8,IF($B28<0,0,IF($B28<B$13,B$9,IF($B28<=B$12,B$22*($B28-B$13)+B$9,B$21*($B28-B$12)+C$21)))) -> 2.5 | D28: =SQRT($B$15^2-($C28*100)^2) -> 84.82924 | E28: =$B$17*0.4+$D28*0.6 -> 70.897544
A29: 0.2 | B29: =$B$7-$A29*$B$2 -> 37.9 | C29: =IF($B29>B$10,B$8,IF($B29<0,0,IF($B29<B$13,B$9,IF($B29<=B$12,B$22*($B29-B$13)+B$9,B$21*($B29-B$12)+C$21)))) -> 2.49815 | D29: =SQRT($B$15^2-($C29*100)^2) -> 85.372512 | E29: =$B$17*0.2+$D29*0.8 -> 78.298009
A30: 0.25 | B30: =$B$7-$A30*$B$2 -> 36.2 | C30: =IF($B30>B$10,B$8,IF($B30<0,0,IF($B30<B$13,B$9,IF($B30<=B$12,B$22*($B30-B$13)+B$9,B$21*($B30-B$12)+C$21)))) -> 2.4667 | D30: =SQRT($B$15^2-($C30*100)^2) -> 94.073966 | E30: =$B$17*0.1+$D30*0.9 -> 89.666569
A31: 0.3 | B31: =$B$7-$A31*$B$2 -> 34.5 | C31: =IF($B31>B$10,B$8,IF($B31<0,0,IF($B31<B$13,B$9,IF($B31<=B$12,B$22*($B31-B$13)+B$9,B$21*($B31-B$12)+C$21)))) -> 2.43525 | D31: =SQRT($B$15^2-($C31*100)^2) -> 101.93907 | E31: =$B$17*0.05+$D31*0.95 -> 99.342118
A32: 0.35 | B32: =$B$7-$A32*$B$2 -> 32.8 | C32: =IF($B32>B$10,B$8,IF($B32<0,0,IF($B32<B$13,B$9,IF($B32<=B$12,B$22*($B32-B$13)+B$9,B$21*($B32-B$12)+C$21)))) -> 2.4038 | D32: =SQRT($B$15^2-($C32*100)^2) -> 109.14878 | E32: =IF($B$16<$D32,$B$16,$D32) -> 109.14878
A33: 0.4 | B33: =$B$7-$A33*$B$2 -> 31.1 | C33: =IF($B33>B$10,B$8,IF($B33<0,0,IF($B33<B$13,B$9,IF($B33<=B$12,B$22*($B33-B$13)+B$9,B$21*($B33-B$12)+C$21)))) -> 2.37235 | D33: =SQRT($B$15^2-($C33*100)^2) -> 115.82554 | E33: =IF($B$16<$D33,$B$16,$D33) -> 115.82554
A34: 0.45 | B34: =$B$7-$A34*$B$2 -> 29.4 | C34: =IF($B34>B$10,B$8,IF($B34<0,0,IF($B34<B$13,B$9,IF($B34<=B$12,B$22*($B34-B$13)+B$9,B$21*($B34-B$12)+C$21)))) -> 2.3409 | D34: =SQRT($B$15^2-($C34*100)^2) -> 122.05684 | E34: =IF($B$16<$D34,$B$16,$D34) -> 122.05684
A35: 0.5 | B35: =$B$7-$A35*$B$2 -> 27.7 | C35: =IF($B35>B$10,B$8,IF($B35<0,0,IF($B35<B$13,B$9,IF($B35<=B$12,B$22*($B35-B$13)+B$9,B$21*($B35-B$12)+C$21)))) -> 2.30945 | D35: =SQRT($B$15^2-($C35*100)^2) -> 127.90781 | E35: =IF($B$16<$D35,$B$16,$D35) -> 127.90781
A36: 0.55 | B36: =$B$7-$A36*$B$2 -> 26 | C36: =IF($B36>B$10,B$8,IF($B36<0,0,IF($B36<B$13,B$9,IF($B36<=B$12,B$22*($B36-B$13)+B$9,B$21*($B36-B$12)+C$21)))) -> 2.278 | D36: =SQRT($B$15^2-($C36*100)^2) -> 133.42848 | E36: =IF($B$16<$D36,$B$16,$D36) -> 133.42848
A37: 0.6 | B37: =$B$7-$A37*$B$2 -> 24.3 | C37: =IF($B37>B$10,B$8,IF($B37<0,0,IF($B37<B$13,B$9,IF($B37<=B$12,B$22*($B37-B$13)+B$9,B$21*($B37-B$12)+C$21)))) -> 2.24655 | D37: =SQRT($B$15^2-($C37*100)^2) -> 138.65832 | E37: =IF($B$16<$D37,$B$16,$D37) -> 138.65832
A38: 0.65 | B38: =$B$7-$A38*$B$2 -> 22.6 | C38: =IF($B38>B$10,B$8,IF($B38<0,0,IF($B38<B$13,B$9,IF($B38<=B$12,B$22*($B38-B$13)+B$9,B$21*($B38-B$12)+C$21)))) -> 2.2151 | D38: =SQRT($B$15^2-($C38*100)^2) -> 143.62911 | E38: =IF($B$16<$D38,$B$16,$D38) -> 143.62911
A39: 0.7 | B39: =$B$7-$A39*$B$2 -> 20.9 | C39: =IF($B39>B$10,B$8,IF($B39<0,0,IF($B39<B$13,B$9,IF($B39<=B$12,B$22*($B39-B$13)+B$9,B$21*($B39-B$12)+C$21)))) -> 2.18365 | D39: =SQRT($B$15^2-($C39*100)^2) -> 148.36687 | E39: =IF($B$16<$D39,$B$16,$D39) -> 148.36687
A40: 0.75 | B40: =$B$7-$A40*$B$2 -> 19.2 | C40: =IF($B40>B$10,B$8,IF($B40<0,0,IF($B40<B$13,B$9,IF($B40<=B$12,B$22*($B40-B$13)+B$9,B$21*($B40-B$12)+C$21)))) -> 2.1522 | D40: =SQRT($B$15^2-($C40*100)^2) -> 152.89327 | E40: =IF($B$16<$D40,$B$16,$D40) -> 152.89327
A41: 0.8 | B41: =$B$7-$A41*$B$2 -> 17.5 | C41: =IF($B41>B$10,B$8,IF($B41<0,0,IF($B41<B$13,B$9,IF($B41<=B$12,B$22*($B41-B$13)+B$9,B$21*($B41-B$12)+C$21)))) -> 2.1041667 | D41: =SQRT($B$15^2-($C41*100)^2) -> 159.4391 | E41: =IF($B$16<$D41,$B$16,$D41) -> 159.4391
A42: 0.85 | B42: =$B$7-$A42*$B$2 -> 15.8 | C42: =IF($B42>B$10,B$8,IF($B42<0,0,IF($B42<B$13,B$9,IF($B42<=B$12,B$22*($B42-B$13)+B$9,B$21*($B42-B$12)+C$21)))) -> 2.0163333 | D42: =SQRT($B$15^2-($C42*100)^2) -> 170.41126 | E42: =IF($B$16<$D42,$B$16,$D42) -> 165
...

Sheet Calc Data 4
A1: Needle | B1: =Chart!$B$8 -> K27
A2: Carb Diameter | B2: =Chart!$D$8 -> 34
A3: Clip position | B3: =Chart!$C$8 -> 2
A4: Distance between clip positions | B4: 1.2
A5: Min distance needle is exposed at idle | B5: 26.4
A6: Needle length | B6: =LOOKUP(LEFT(Chart!$B$8,1),'Needle Data'!$J2:$J3,'Needle Data'!$K2:$K3) -> 73.5
A7: Needle position at idle | B7: =$B$6 - $B$5 - ($B$3-1)*$B$4 + $B$18 + ($B$2 - 34)/2 -> 45.9
A8: a | B8: =VLOOKUP($B$1,'Needle Data'!$A$2:$G$113,2,0) -> 2.5
A9: b | B9: =VLOOKUP($B$1,'Needle Data'!$A$2:$G$113,3,0) -> 1.8
A10: c | B10: =VLOOKUP($B$1,'Needle Data'!$A$2:$G$113,4,0) -> 44
A11: d | B11: =VLOOKUP($B$1,'Needle Data'!$A$2:$G$113,5,0)
A12: e | B12: =VLOOKUP($B$1,'Needle Data'!$A$2:$G$113,6,0)
A13: f | B13: =VLOOKUP($B$1,'Needle Data'!$A$2:$G$113,7,0)
A14: tapers | B14: =IF($B$13,3,IF($B$12,2,1)) -> 1
A15: Needle Jet | B15: =Chart!$E$8 -> 264
A16: HD | B16: =Chart!$I$8 -> 170
A17: ND | B17: =Chart!$H$8 -> 50
A18: Needle Offset because of Needle JET | B18: =LOOKUP(Chart!$F$8,'Needle Data'!$M2:$M4,'Needle Data'!$N2:$N4) -> 0
A20: taper | B20: k | C20: d
A21: 1 | B21: =IF(B$14=1,(B$8-B$9)/B$10,(B$8-B$11)/(B$10-B$12)) -> 0.015909091 | C21: =IF(B$14=1,B$9,B$11) -> 1.8
A22: 2 | B22: =IF(B$14=1,0,(B$11-B$9)/(B$12-B$13)) -> 0 | C22: =IF(B$14=1,0,B$9) -> 0
A24: Throttle Position | B24: Needle Position | C24: Needle Diameter | D24: HD equiv. | E24: Overall
A25: 0 | B25: =$B$7-$A25*$B$2 -> 45.9 | C25: =IF($B25>B$10,B$8,IF($B25<0,0,IF($B25<B$13,B$9,IF($B25<=B$12,B$22*($B25-B$13)+B$9,B$21*($B25-B$12)+C$21)))) -> 2.5 | D25: =SQRT($B$15^2-($C25*100)^2) -> 84.82924 | E25: =$B$17*1+$D25*0 -> 50
A26: 0.05 | B26: =$B$7-$A26*$B$2 -> 44.2 | C26: =IF($B26>B$10,B$8,IF($B26<0,0,IF($B26<B$13,B$9,IF($B26<=B$12,B$22*($B26-B$13)+B$9,B$21*($B26-B$12)+C$21)))) -> 2.5 | D26: =SQRT($B$15^2-($C26*100)^2) -> 84.82924 | E26: =$B$17*0.8+$D26*0.2 -> 56.965848
A27: 0.1 | B27: =$B$7-$A27*$B$2 -> 42.5 | C27: =IF($B27>B$10,B$8,IF($B27<0,0,IF($B27<B$13,B$9,IF($B27<=B$12,B$22*($B27-B$13)+B$9,B$21*($B27-B$12)+C$21)))) -> 2.4761364 | D27: =SQRT($B$15^2-($C27*100)^2) -> 91.561384 | E27: =$B$17*0.6+$D27*0.4 -> 66.624554
A28: 0.15 | B28: =$B$7-$A28*$B$2 -> 40.8 | C28: =IF($B28>B$10,B$8,IF($B28<0,0,IF($B28<B$13,B$9,IF($B28<=B$12,B$22*($B28-B$13)+B$9,B$21*($B28-B$12)+C$21)))) -> 2.4490909 | D28: =SQRT($B$15^2-($C28*100)^2) -> 98.567425 | E28: =$B$17*0.4+$D28*0.6 -> 79.140455
A29: 0.2 | B29: =$B$7-$A29*$B$2 -> 39.1 | C29: =IF($B29>B$10,B$8,IF($B29<0,0,IF($B29<B$13,B$9,IF($B29<=B$12,B$22*($B29-B$13)+B$9,B$21*($B29-B$12)+C$21)))) -> 2.4220455 | D29: =SQRT($B$15^2-($C29*100)^2) -> 105.03789 | E29: =$B$17*0.2+$D29*0.8 -> 94.030311
A30: 0.25 | B30: =$B$7-$A30*$B$2 -> 37.4 | C30: =IF($B30>B$10,B$8,IF($B30<0,0,IF($B30<B$13,B$9,IF($B30<=B$12,B$22*($B30-B$13)+B$9,B$21*($B30-B$12)+C$21)))) -> 2.395 | D30: =SQRT($B$15^2-($C30*100)^2) -> 111.06642 | E30: =$B$17*0.1+$D30*0.9 -> 104.95978
A31: 0.3 | B31: =$B$7-$A31*$B$2 -> 35.7 | C31: =IF($B31>B$10,B$8,IF($B31<0,0,IF($B31<B$13,B$9,IF($B31<=B$12,B$22*($B31-B$13)+B$9,B$21*($B31-B$12)+C$21)))) -> 2.3679545 | D31: =SQRT($B$15^2-($C31*100)^2) -> 116.72152 | E31: =$B$17*0.05+$D31*0.95 -> 113.38544
A32: 0.35 | B32: =$B$7-$A32*$B$2 -> 34 | C32: =IF($B32>B$10,B$8,IF($B32<0,0,IF($B32<B$13,B$9,IF($B32<=B$12,B$22*($B32-B$13)+B$9,B$21*($B32-B$12)+C$21)))) -> 2.3409091 | D32: =SQRT($B$15^2-($C32*100)^2) -> 122.0551 | E32: =IF($B$16<$D32,$B$16,$D32) -> 122.0551
A33: 0.4 | B33: =$B$7-$A33*$B$2 -> 32.3 | C33: =IF($B33>B$10,B$8,IF($B33<0,0,IF($B33<B$13,B$9,IF($B33<=B$12,B$22*($B33-B$13)+B$9,B$21*($B33-B$12)+C$21)))) -> 2.3138636 | D33: =SQRT($B$15^2-($C33*100)^2) -> 127.10763 | E33: =IF($B$16<$D33,$B$16,$D33) -> 127.10763
A34: 0.45 | B34: =$B$7-$A34*$B$2 -> 30.6 | C34: =IF($B34>B$10,B$8,IF($B34<0,0,IF($B34<B$13,B$9,IF($B34<=B$12,B$22*($B34-B$13)+B$9,B$21*($B34-B$12)+C$21)))) -> 2.2868182 | D34: =SQRT($B$15^2-($C34*100)^2) -> 131.91143 | E34: =IF($B$16<$D34,$B$16,$D34) -> 131.91143
A35: 0.5 | B35: =$B$7-$A35*$B$2 -> 28.9 | C35: =IF($B35>B$10,B$8,IF($B35<0,0,IF($B35<B$13,B$9,IF($B35<=B$12,B$22*($B35-B$13)+B$9,B$21*($B35-B$12)+C$21)))) -> 2.2597727 | D35: =SQRT($B$15^2-($C35*100)^2) -> 136.49276 | E35: =IF($B$16<$D35,$B$16,$D35) -> 136.49276
A36: 0.55 | B36: =$B$7-$A36*$B$2 -> 27.2 | C36: =IF($B36>B$10,B$8,IF($B36<0,0,IF($B36<B$13,B$9,IF($B36<=B$12,B$22*($B36-B$13)+B$9,B$21*($B36-B$12)+C$21)))) -> 2.2327273 | D36: =SQRT($B$15^2-($C36*100)^2) -> 140.87331 | E36: =IF($B$16<$D36,$B$16,$D36) -> 140.87331
A37: 0.6 | B37: =$B$7-$A37*$B$2 -> 25.5 | C37: =IF($B37>B$10,B$8,IF($B37<0,0,IF($B37<B$13,B$9,IF($B37<=B$12,B$22*($B37-B$13)+B$9,B$21*($B37-B$12)+C$21)))) -> 2.2056818 | D37: =SQRT($B$15^2-($C37*100)^2) -> 145.07128 | E37: =IF($B$16<$D37,$B$16,$D37) -> 145.07128
A38: 0.65 | B38: =$B$7-$A38*$B$2 -> 23.8 | C38: =IF($B38>B$10,B$8,IF($B38<0,0,IF($B38<B$13,B$9,IF($B38<=B$12,B$22*($B38-B$13)+B$9,B$21*($B38-B$12)+C$21)))) -> 2.1786364 | D38: =SQRT($B$15^2-($C38*100)^2) -> 149.1021 | E38: =IF($B$16<$D38,$B$16,$D38) -> 149.1021
A39: 0.7 | B39: =$B$7-$A39*$B$2 -> 22.1 | C39: =IF($B39>B$10,B$8,IF($B39<0,0,IF($B39<B$13,B$9,IF($B39<=B$12,B$22*($B39-B$13)+B$9,B$21*($B39-B$12)+C$21)))) -> 2.1515909 | D39: =SQRT($B$15^2-($C39*100)^2) -> 152.97897 | E39: =IF($B$16<$D39,$B$16,$D39) -> 152.97897
A40: 0.75 | B40: =$B$7-$A40*$B$2 -> 20.4 | C40: =IF($B40>B$10,B$8,IF($B40<0,0,IF($B40<B$13,B$9,IF($B40<=B$12,B$22*($B40-B$13)+B$9,B$21*($B40-B$12)+C$21)))) -> 2.1245455 | D40: =SQRT($B$15^2-($C40*100)^2) -> 156.71332 | E40: =IF($B$16<$D40,$B$16,$D40) -> 156.71332
A41: 0.8 | B41: =$B$7-$A41*$B$2 -> 18.7 | C41: =IF($B41>B$10,B$8,IF($B41<0,0,IF($B41<B$13,B$9,IF($B41<=B$12,B$22*($B41-B$13)+B$9,B$21*($B41-B$12)+C$21)))) -> 2.0975 | D41: =SQRT($B$15^2-($C41*100)^2) -> 160.31512 | E41: =IF($B$16<$D41,$B$16,$D41) -> 160.31512
A42: 0.85 | B42: =$B$7-$A42*$B$2 -> 17 | C42: =IF($B42>B$10,B$8,IF($B42<0,0,IF($B42<B$13,B$9,IF($B42<=B$12,B$22*($B42-B$13)+B$9,B$21*($B42-B$12)+C$21)))) -> 2.0704545 | D42: =SQRT($B$15^2-($C42*100)^2) -> 163.7931 | E42: =IF($B$16<$D42,$B$16,$D42) -> 163.7931
...

Sheet Calc Data 5
A1: Needle | B1: =Chart!$B$9 -> U16
A2: Carb Diameter | B2: =Chart!$D$9 -> 32
A3: Clip position | B3: =Chart!$C$9 -> 2
A4: Distance between clip positions | B4: 1.2
A5: Min distance needle is exposed at idle | B5: 26.4
A6: Needle length | B6: =LOOKUP(LEFT(Chart!$B$9,1),'Needle Data'!$J2:$J3,'Needle Data'!$K2:$K3) -> 68
A7: Needle position at idle | B7: =$B$6 - $B$5 - ($B$3-1)*$B$4 + $B$18 + ($B$2 - 34)/2 -> 41.4
A8: a | B8: =VLOOKUP($B$1,'Needle Data'!$A$2:$G$113,2,0) -> 2.5
A9: b | B9: =VLOOKUP($B$1,'Needle Data'!$A$2:$G$113,3,0) -> 1.8
A10: c | B10: =VLOOKUP($B$1,'Needle Data'!$A$2:$G$113,4,0) -> 32
A11: d | B11: =VLOOKUP($B$1,'Needle Data'!$A$2:$G$113,5,0)
A12: e | B12: =VLOOKUP($B$1,'Needle Data'!$A$2:$G$113,6,0)
A13: f | B13: =VLOOKUP($B$1,'Needle Data'!$A$2:$G$113,7,0)
A14: tapers | B14: =IF($B$13,3,IF($B$12,2,1)) -> 1
A15: Needle Jet | B15: =Chart!$E$9 -> 262
A16: HD | B16: =Chart!$I$9 -> 150
A17: ND | B17: =Chart!$H$9 -> 44
A18: Needle Offset because of Needle JET | B18: =LOOKUP(Chart!$F$9,'Needle Data'!$M2:$M4,'Needle Data'!$N2:$N4) -> 2
A20: taper | B20: k | C20: d
A21: 1 | B21: =IF(B$14=1,(B$8-B$9)/B$10,(B$8-B$11)/(B$10-B$12)) -> 0.021875 | C21: =IF(B$14=1,B$9,B$11) -> 1.8
A22: 2 | B22: =IF(B$14=1,0,(B$11-B$9)/(B$12-B$13)) -> 0 | C22: =IF(B$14=1,0,B$9) -> 0
A24: Throttle Position | B24: Needle Position | C24: Needle Diameter | D24: HD equiv. | E24: Overall
A25: 0 | B25: =$B$7-$A25*$B$2 -> 41.4 | C25: =IF($B25>B$10,B$8,IF($B25<0,0,IF($B25<B$13,B$9,IF($B25<=B$12,B$22*($B25-B$13)+B$9,B$21*($B25-B$12)+C$21)))) -> 2.5 | D25: =SQRT($B$15^2-($C25*100)^2) -> 78.383672 | E25: =$B$17*1+$D25*0 -> 44
A26: 0.05 | B26: =$B$7-$A26*$B$2 -> 39.8 | C26: =IF($B26>B$10,B$8,IF($B26<0,0,IF($B26<B$13,B$9,IF($B26<=B$12,B$22*($B26-B$13)+B$9,B$21*($B26-B$12)+C$21)))) -> 2.5 | D26: =SQRT($B$15^2-($C26*100)^2) -> 78.383672 | E26: =$B$17*0.8+$D26*0.2 -> 50.876734
A27: 0.1 | B27: =$B$7-$A27*$B$2 -> 38.2 | C27: =IF($B27>B$10,B$8,IF($B27<0,0,IF($B27<B$13,B$9,IF($B27<=B$12,B$22*($B27-B$13)+B$9,B$21*($B27-B$12)+C$21)))) -> 2.5 | D27: =SQRT($B$15^2-($C27*100)^2) -> 78.383672 | E27: =$B$17*0.6+$D27*0.4 -> 57.753469
A28: 0.15 | B28: =$B$7-$A28*$B$2 -> 36.6 | C28: =IF($B28>B$10,B$8,IF($B28<0,0,IF($B28<B$13,B$9,IF($B28<=B$12,B$22*($B28-B$13)+B$9,B$21*($B28-B$12)+C$21)))) -> 2.5 | D28: =SQRT($B$15^2-($C28*100)^2) -> 78.383672 | E28: =$B$17*0.4+$D28*0.6 -> 64.630203
A29: 0.2 | B29: =$B$7-$A29*$B$2 -> 35 | C29: =IF($B29>B$10,B$8,IF($B29<0,0,IF($B29<B$13,B$9,IF($B29<=B$12,B$22*($B29-B$13)+B$9,B$21*($B29-B$12)+C$21)))) -> 2.5 | D29: =SQRT($B$15^2-($C29*100)^2) -> 78.383672 | E29: =$B$17*0.2+$D29*0.8 -> 71.506937
A30: 0.25 | B30: =$B$7-$A30*$B$2 -> 33.4 | C30: =IF($B30>B$10,B$8,IF($B30<0,0,IF($B30<B$13,B$9,IF($B30<=B$12,B$22*($B30-B$13)+B$9,B$21*($B30-B$12)+C$21)))) -> 2.5 | D30: =SQRT($B$15^2-($C30*100)^2) -> 78.383672 | E30: =$B$17*0.1+$D30*0.9 -> 74.945305
A31: 0.3 | B31: =$B$7-$A31*$B$2 -> 31.8 | C31: =IF($B31>B$10,B$8,IF($B31<0,0,IF($B31<B$13,B$9,IF($B31<=B$12,B$22*($B31-B$13)+B$9,B$21*($B31-B$12)+C$21)))) -> 2.495625 | D31: =SQRT($B$15^2-($C31*100)^2) -> 79.765648 | E31: =$B$17*0.05+$D31*0.95 -> 77.977366
A32: 0.35 | B32: =$B$7-$A32*$B$2 -> 30.2 | C32: =IF($B32>B$10,B$8,IF($B32<0,0,IF($B32<B$13,B$9,IF($B32<=B$12,B$22*($B32-B$13)+B$9,B$21*($B32-B$12)+C$21)))) -> 2.460625 | D32: =SQRT($B$15^2-($C32*100)^2) -> 89.984699 | E32: =IF($B$16<$D32,$B$16,$D32) -> 89.984699
A33: 0.4 | B33: =$B$7-$A33*$B$2 -> 28.6 | C33: =IF($B33>B$10,B$8,IF($B33<0,0,IF($B33<B$13,B$9,IF($B33<=B$12,B$22*($B33-B$13)+B$9,B$21*($B33-B$12)+C$21)))) -> 2.425625 | D33: =SQRT($B$15^2-($C33*100)^2) -> 99.032488 | E33: =IF($B$16<$D33,$B$16,$D33) -> 99.032488
A34: 0.45 | B34: =$B$7-$A34*$B$2 -> 27 | C34: =IF($B34>B$10,B$8,IF($B34<0,0,IF($B34<B$13,B$9,IF($B34<=B$12,B$22*($B34-B$13)+B$9,B$21*($B34-B$12)+C$21)))) -> 2.390625 | D34: =SQRT($B$15^2-($C34*100)^2) -> 107.20598 | E34: =IF($B$16<$D34,$B$16,$D34) -> 107.20598
A35: 0.5 | B35: =$B$7-$A35*$B$2 -> 25.4 | C35: =IF($B35>B$10,B$8,IF($B35<0,0,IF($B35<B$13,B$9,IF($B35<=B$12,B$22*($B35-B$13)+B$9,B$21*($B35-B$12)+C$21)))) -> 2.355625 | D35: =SQRT($B$15^2-($C35*100)^2) -> 114.69223 | E35: =IF($B$16<$D35,$B$16,$D35) -> 114.69223
A36: 0.55 | B36: =$B$7-$A36*$B$2 -> 23.8 | C36: =IF($B36>B$10,B$8,IF($B36<0,0,IF($B36<B$13,B$9,IF($B36<=B$12,B$22*($B36-B$13)+B$9,B$21*($B36-B$12)+C$21)))) -> 2.320625 | D36: =SQRT($B$15^2-($C36*100)^2) -> 121.61824 | E36: =IF($B$16<$D36,$B$16,$D36) -> 121.61824
A37: 0.6 | B37: =$B$7-$A37*$B$2 -> 22.2 | C37: =IF($B37>B$10,B$8,IF($B37<0,0,IF($B37<B$13,B$9,IF($B37<=B$12,B$22*($B37-B$13)+B$9,B$21*($B37-B$12)+C$21)))) -> 2.285625 | D37: =SQRT($B$15^2-($C37*100)^2) -> 128.07491 | E37: =IF($B$16<$D37,$B$16,$D37) -> 128.07491
A38: 0.65 | B38: =$B$7-$A38*$B$2 -> 20.6 | C38: =IF($B38>B$10,B$8,IF($B38<0,0,IF($B38<B$13,B$9,IF($B38<=B$12,B$22*($B38-B$13)+B$9,B$21*($B38-B$12)+C$21)))) -> 2.250625 | D38: =SQRT($B$15^2-($C38*100)^2) -> 134.13005 | E38: =IF($B$16<$D38,$B$16,$D38) -> 134.13005
A39: 0.7 | B39: =$B$7-$A39*$B$2 -> 19 | C39: =IF($B39>B$10,B$8,IF($B39<0,0,IF($B39<B$13,B$9,IF($B39<=B$12,B$22*($B39-B$13)+B$9,B$21*($B39-B$12)+C$21)))) -> 2.215625 | D39: =SQRT($B$15^2-($C39*100)^2) -> 139.83583 | E39: =IF($B$16<$D39,$B$16,$D39) -> 139.83583
A40: 0.75 | B40: =$B$7-$A40*$B$2 -> 17.4 | C40: =IF($B40>B$10,B$8,IF($B40<0,0,IF($B40<B$13,B$9,IF($B40<=B$12,B$22*($B40-B$13)+B$9,B$21*($B40-B$12)+C$21)))) -> 2.180625 | D40: =SQRT($B$15^2-($C40*100)^2) -> 145.23342 | E40: =IF($B$16<$D40,$B$16,$D40) -> 145.23342
A41: 0.8 | B41: =$B$7-$A41*$B$2 -> 15.8 | C41: =IF($B41>B$10,B$8,IF($B41<0,0,IF($B41<B$13,B$9,IF($B41<=B$12,B$22*($B41-B$13)+B$9,B$21*($B41-B$12)+C$21)))) -> 2.145625 | D41: =SQRT($B$15^2-($C41*100)^2) -> 150.35602 | E41: =IF($B$16<$D41,$B$16,$D41) -> 150
A42: 0.85 | B42: =$B$7-$A42*$B$2 -> 14.2 | C42: =IF($B42>B$10,B$8,IF($B42<0,0,IF($B42<B$13,B$9,IF($B42<=B$12,B$22*($B42-B$13)+B$9,B$21*($B42-B$12)+C$21)))) -> 2.110625 | D42: =SQRT($B$15^2-($C42*100)^2) -> 155.23086 | E42: =IF($B$16<$D42,$B$16,$D42) -> 150
...
